<?xml version="1.0"?>
<robot xmlns:xacro="http://www.ros.org/wiki/xacro">

  <xacro:include filename="$(find uhvat_description)/urdf/uhvat.gazebo.xacro" />
  <xacro:include filename="$(find uhvat_description)/urdf/uhvat.transmission.xacro" />
  <xacro:include filename="$(find uhvat_description)/urdf/utilities.urdf.xacro" />

  <xacro:property name="safety_controller_k_pos" value="100" />
  <xacro:property name="safety_controller_k_vel" value="100" />
  <xacro:property name="joint_damping" value="0.4" />
  <xacro:property name="joint_static_friction" value="0.4" />
  <xacro:property name="max_effort" value="300"/>
  <xacro:property name="max_velocity" value="10"/>

  <xacro:macro name="uhvat" params="parent name *origin">

    <!-- Connection joint -->
    <joint name="${name}_joint" type="fixed">
      <xacro:insert_block name="origin"/>
      <parent link="${parent}"/>
      <child link="${name}_link_0"/>
    </joint>

    <link name="${name}_link_0">
      <inertial>
        <origin xyz="0 0 0" rpy="0 0 0" />
        <mass value="0.1" />
        <inertia
          ixx="1.0"
          ixy="0.0"
          ixz="0.0"
          iyy="1.0"
          iyz="0.0"
          izz="1.0" />
        </inertial>
      <visual>
        <origin xyz="0 0 0" rpy="0 0 0" />
        <geometry>
          <mesh
            filename="package://uhvat_description/meshes/motor_mount.stl" 
            scale="0.001 0.001 0.001" />
        </geometry>
        <material name="Grey"/>
      </visual>
      <collision>
        <origin xyz="0 0 0" rpy="0 0 0" />
        <geometry>
          <mesh
            filename="package://uhvat_description/meshes/motor_mount.stl" 
            scale="0.001 0.001 0.001" />
        </geometry>
      </collision>
    </link>


    <!-- left finger -->
    <joint name="${name}_joint_1" type="revolute">
      <origin
        xyz="-0.045 -0.035 0"
        rpy="0 0 ${PI}" />
      <parent
        link="${name}_link_0" />
      <child
        link="${name}_link_1" />
      <axis xyz="0 0 1" />
      <limit lower="${-170 * PI / 180}" upper="${170 * PI / 180}"
             effort="${max_effort}" velocity="${max_velocity}" />
      <dynamics damping="${joint_damping}" friction="${joint_static_friction}"/>
    </joint>
    <link name="${name}_link_1">
      <inertial>
        <origin xyz="0 0 0" rpy="0 0 0" />
        <mass value="1" />
        <inertia
          ixx="1.0"
          ixy="0.0"
          ixz="0.0"
          iyy="0.0"
          iyz="0.0"
          izz="1.0" />
        </inertial>
      <visual>
        <origin xyz="0.015 0.025 -0.02" rpy="0 0 0" />
        <geometry>
          <mesh
            filename="package://uhvat_description/meshes/festolike_finger.stl" 
            scale="0.0013 0.0013 0.002" />
        </geometry>
        <material name="Green"/>
      </visual>
      <collision>
        <origin xyz="0.015 0.025 -0.02" rpy="0 0 0" />
        <geometry>
          <mesh
            filename="package://uhvat_description/meshes/festolike_finger.stl" 
            scale="0.0013 0.0013 0.002" />
        </geometry>
      </collision>      
    </link>


    <!-- right finger -->
    <joint name="${name}_joint_2" type="revolute">
      <origin
        xyz="-0.045 0.035 0"
        rpy="0 0 0" />
      <parent
        link="${name}_link_0" />
      <child
        link="${name}_link_2" />
      <axis xyz="0 0 1" />
      <limit lower="${-170 * PI / 180}" upper="${170 * PI / 180}"
             effort="${max_effort}" velocity="${max_velocity}" />
      <dynamics damping="${joint_damping}" friction="${joint_static_friction}"/>
    </joint>
    <link name="${name}_link_2">
      <inertial>
        <origin xyz="0 0 0" rpy="0 0 0" />
        <mass value="1" />
        <inertia
          ixx="1.0"
          ixy="0.0"
          ixz="0.0"
          iyy="0.0"
          iyz="0.0"
          izz="1.0" />
        </inertial>
      <visual>
        <origin xyz="0.025 0.025 -0.02" rpy="0 0 0" />
        <geometry>
          <mesh
            filename="package://uhvat_description/meshes/festolike_finger.stl" 
            scale="0.0013 0.0013 0.002" />
        </geometry>
        <material name="Orange"/>
      </visual>
      <collision>
        <origin xyz="0.025 0.025 -0.02" rpy="0 0 0" />
        <geometry>
          <mesh
            filename="package://uhvat_description/meshes/festolike_finger.stl" 
            scale="0.0013 0.0013 0.002" />
        </geometry>
      </collision>
    </link>



    <!--Extensions -->
    <xacro:uhvat_gazebo name="${name}" />
    <xacro:uhvat_transmission name="${name}"/>

  </xacro:macro>

</robot>
